<sdf version='1.6'>
  <world name='default'>
    <light name='sun' type='directional'>
      <cast_shadows>1</cast_shadows>
      <pose frame=''>0 0 10 0 -0 0</pose>
      <diffuse>0.8 0.8 0.8 1</diffuse>
      <specular>0.1 0.1 0.1 1</specular>
      <attenuation>
        <range>1000</range>
        <constant>0.9</constant>
        <linear>0.01</linear>
        <quadratic>0.001</quadratic>
      </attenuation>
      <direction>-0.5 0.5 -1</direction>
    </light>
    <model name='ground_plane'>
      <static>1</static>
      <link name='link'>
        <collision name='collision'>
          <geometry>
            <plane>
              <normal>0 0 1</normal>
              <size>100 100</size>
            </plane>
          </geometry>
          <surface>
            <friction>
              <ode>
                <mu>100</mu>
                <mu2>50</mu2>
              </ode>
              <torsional>
                <ode/>
              </torsional>
            </friction>
            <contact>
              <ode/>
            </contact>
            <bounce/>
          </surface>
          <max_contacts>10</max_contacts>
        </collision>
        <visual name='visual'>
          <cast_shadows>0</cast_shadows>
          <geometry>
            <plane>
              <normal>0 0 1</normal>
              <size>100 100</size>
            </plane>
          </geometry>
          <material>
            <script>
              <uri>file://media/materials/scripts/gazebo.material</uri>
              <name>Gazebo/Grey</name>
            </script>
          </material>
        </visual>
        <self_collide>0</self_collide>
        <kinematic>0</kinematic>
      </link>
    </model>
    <gravity>0 0 -9.8</gravity>
    <magnetic_field>6e-06 2.3e-05 -4.2e-05</magnetic_field>
    <atmosphere type='adiabatic'/>
    <physics name='default_physics' default='0' type='ode'>
      <max_step_size>0.001</max_step_size>
      <real_time_factor>100</real_time_factor>
      <real_time_update_rate>0</real_time_update_rate>
    </physics>
    <scene>
      <ambient>0.4 0.4 0.4 1</ambient>
      <background>0.7 0.7 0.7 1</background>
      <shadows>1</shadows>
    </scene>
    <spherical_coordinates>
      <surface_model>EARTH_WGS84</surface_model>
      <latitude_deg>0</latitude_deg>
      <longitude_deg>0</longitude_deg>
      <elevation>0</elevation>
      <heading_deg>0</heading_deg>
    </spherical_coordinates>
    <model name='octa'>
      <pose frame=''>0 0 0 0 -0 0</pose>
      <link name='Wall_11'>
        <collision name='Wall_11_Collision'>
          <geometry>
            <box>
              <size>12.15 0.15 2.5</size>
            </box>
          </geometry>
          <pose frame=''>0 0 1.25 0 -0 0</pose>
          <max_contacts>10</max_contacts>
          <surface>
            <contact>
              <ode/>
            </contact>
            <bounce/>
            <friction>
              <torsional>
                <ode/>
              </torsional>
              <ode/>
            </friction>
          </surface>
        </collision>
        <visual name='Wall_11_Visual'>
          <pose frame=''>0 0 1.25 0 -0 0</pose>
          <geometry>
            <box>
              <size>12.15 0.15 2.5</size>
            </box>
          </geometry>
          <material>
            <script>
              <uri>file://media/materials/scripts/gazebo.material</uri>
              <name>Gazebo/Grey</name>
            </script>
            <ambient>1 1 1 1</ambient>
          </material>
          <meta>
            <layer>0</layer>
          </meta>
        </visual>
        <pose frame=''>0 -10 0 0 -0 0</pose>
        <self_collide>0</self_collide>
        <kinematic>0</kinematic>
      </link>
      <link name='Wall_12'>
        <collision name='Wall_12_Collision'>
          <geometry>
            <box>
              <size>5.80685 0.15 2.5</size>
            </box>
          </geometry>
          <pose frame=''>0 0 1.25 0 -0 0</pose>
          <max_contacts>10</max_contacts>
          <surface>
            <contact>
              <ode/>
            </contact>
            <bounce/>
            <friction>
              <torsional>
                <ode/>
              </torsional>
              <ode/>
            </friction>
          </surface>
        </collision>
        <visual name='Wall_12_Visual'>
          <pose frame=''>0 0 1.25 0 -0 0</pose>
          <geometry>
            <box>
              <size>5.80685 0.15 2.5</size>
            </box>
          </geometry>
          <material>
            <script>
              <uri>file://media/materials/scripts/gazebo.material</uri>
              <name>Gazebo/Grey</name>
            </script>
            <ambient>1 1 1 1</ambient>
          </material>
          <meta>
            <layer>0</layer>
          </meta>
        </visual>
        <pose frame=''>8 -8 0 0 -0 0.785398</pose>
        <self_collide>0</self_collide>
        <kinematic>0</kinematic>
      </link>
      <link name='Wall_13'>
        <collision name='Wall_13_Collision'>
          <geometry>
            <box>
              <size>12.15 0.15 2.5</size>
            </box>
          </geometry>
          <pose frame=''>0 0 1.25 0 -0 0</pose>
          <max_contacts>10</max_contacts>
          <surface>
            <contact>
              <ode/>
            </contact>
            <bounce/>
            <friction>
              <torsional>
                <ode/>
              </torsional>
              <ode/>
            </friction>
          </surface>
        </collision>
        <visual name='Wall_13_Visual'>
          <pose frame=''>0 0 1.25 0 -0 0</pose>
          <geometry>
            <box>
              <size>12.15 0.15 2.5</size>
            </box>
          </geometry>
          <material>
            <script>
              <uri>file://media/materials/scripts/gazebo.material</uri>
              <name>Gazebo/Grey</name>
            </script>
            <ambient>1 1 1 1</ambient>
          </material>
          <meta>
            <layer>0</layer>
          </meta>
        </visual>
        <pose frame=''>10 0 0 0 -0 1.5708</pose>
        <self_collide>0</self_collide>
        <kinematic>0</kinematic>
      </link>
      <link name='Wall_14'>
        <collision name='Wall_14_Collision'>
          <geometry>
            <box>
              <size>5.80685 0.15 2.5</size>
            </box>
          </geometry>
          <pose frame=''>0 0 1.25 0 -0 0</pose>
          <max_contacts>10</max_contacts>
          <surface>
            <contact>
              <ode/>
            </contact>
            <bounce/>
            <friction>
              <torsional>
                <ode/>
              </torsional>
              <ode/>
            </friction>
          </surface>
        </collision>
        <visual name='Wall_14_Visual'>
          <pose frame=''>0 0 1.25 0 -0 0</pose>
          <geometry>
            <box>
              <size>5.80685 0.15 2.5</size>
            </box>
          </geometry>
          <material>
            <script>
              <uri>file://media/materials/scripts/gazebo.material</uri>
              <name>Gazebo/Grey</name>
            </script>
            <ambient>1 1 1 1</ambient>
          </material>
          <meta>
            <layer>0</layer>
          </meta>
        </visual>
        <pose frame=''>8 8 0 0 -0 2.35619</pose>
        <self_collide>0</self_collide>
        <kinematic>0</kinematic>
      </link>
      <link name='Wall_15'>
        <collision name='Wall_15_Collision'>
          <geometry>
            <box>
              <size>12.15 0.15 2.5</size>
            </box>
          </geometry>
          <pose frame=''>0 0 1.25 0 -0 0</pose>
          <max_contacts>10</max_contacts>
          <surface>
            <contact>
              <ode/>
            </contact>
            <bounce/>
            <friction>
              <torsional>
                <ode/>
              </torsional>
              <ode/>
            </friction>
          </surface>
        </collision>
        <visual name='Wall_15_Visual'>
          <pose frame=''>0 0 1.25 0 -0 0</pose>
          <geometry>
            <box>
              <size>12.15 0.15 2.5</size>
            </box>
          </geometry>
          <material>
            <script>
              <uri>file://media/materials/scripts/gazebo.material</uri>
              <name>Gazebo/Grey</name>
            </script>
            <ambient>1 1 1 1</ambient>
          </material>
          <meta>
            <layer>0</layer>
          </meta>
        </visual>
        <pose frame=''>0 10 0 0 -0 3.14159</pose>
        <self_collide>0</self_collide>
        <kinematic>0</kinematic>
      </link>
      <link name='Wall_16'>
        <collision name='Wall_16_Collision'>
          <geometry>
            <box>
              <size>5.80685 0.15 2.5</size>
            </box>
          </geometry>
          <pose frame=''>0 0 1.25 0 -0 0</pose>
          <max_contacts>10</max_contacts>
          <surface>
            <contact>
              <ode/>
            </contact>
            <bounce/>
            <friction>
              <torsional>
                <ode/>
              </torsional>
              <ode/>
            </friction>
          </surface>
        </collision>
        <visual name='Wall_16_Visual'>
          <pose frame=''>0 0 1.25 0 -0 0</pose>
          <geometry>
            <box>
              <size>5.80685 0.15 2.5</size>
            </box>
          </geometry>
          <material>
            <script>
              <uri>file://media/materials/scripts/gazebo.material</uri>
              <name>Gazebo/Grey</name>
            </script>
            <ambient>1 1 1 1</ambient>
          </material>
          <meta>
            <layer>0</layer>
          </meta>
        </visual>
        <pose frame=''>-8 8 0 0 0 -2.35619</pose>
        <self_collide>0</self_collide>
        <kinematic>0</kinematic>
      </link>
      <link name='Wall_17'>
        <collision name='Wall_17_Collision'>
          <geometry>
            <box>
              <size>12.15 0.15 2.5</size>
            </box>
          </geometry>
          <pose frame=''>0 0 1.25 0 -0 0</pose>
          <max_contacts>10</max_contacts>
          <surface>
            <contact>
              <ode/>
            </contact>
            <bounce/>
            <friction>
              <torsional>
                <ode/>
              </torsional>
              <ode/>
            </friction>
          </surface>
        </collision>
        <visual name='Wall_17_Visual'>
          <pose frame=''>0 0 1.25 0 -0 0</pose>
          <geometry>
            <box>
              <size>12.15 0.15 2.5</size>
            </box>
          </geometry>
          <material>
            <script>
              <uri>file://media/materials/scripts/gazebo.material</uri>
              <name>Gazebo/Grey</name>
            </script>
            <ambient>1 1 1 1</ambient>
          </material>
          <meta>
            <layer>0</layer>
          </meta>
        </visual>
        <pose frame=''>-10 0 0 0 0 -1.5708</pose>
        <self_collide>0</self_collide>
        <kinematic>0</kinematic>
      </link>
      <link name='Wall_18'>
        <collision name='Wall_18_Collision'>
          <geometry>
            <box>
              <size>5.80685 0.15 2.5</size>
            </box>
          </geometry>
          <pose frame=''>0 0 1.25 0 -0 0</pose>
          <max_contacts>10</max_contacts>
          <surface>
            <contact>
              <ode/>
            </contact>
            <bounce/>
            <friction>
              <torsional>
                <ode/>
              </torsional>
              <ode/>
            </friction>
          </surface>
        </collision>
        <visual name='Wall_18_Visual'>
          <pose frame=''>0 0 1.25 0 -0 0</pose>
          <geometry>
            <box>
              <size>5.80685 0.15 2.5</size>
            </box>
          </geometry>
          <material>
            <script>
              <uri>file://media/materials/scripts/gazebo.material</uri>
              <name>Gazebo/Grey</name>
            </script>
            <ambient>1 1 1 1</ambient>
          </material>
          <meta>
            <layer>0</layer>
          </meta>
        </visual>
        <pose frame=''>-8 -8 0 0 0 -0.785398</pose>
        <self_collide>0</self_collide>
        <kinematic>0</kinematic>
      </link>
      <link name='Wall_2'>
        <collision name='Wall_2_Collision'>
          <geometry>
            <box>
              <size>8.15 0.15 2.5</size>
            </box>
          </geometry>
          <pose frame=''>0 0 1.25 0 -0 0</pose>
          <max_contacts>10</max_contacts>
          <surface>
            <contact>
              <ode/>
            </contact>
            <bounce/>
            <friction>
              <torsional>
                <ode/>
              </torsional>
              <ode/>
            </friction>
          </surface>
        </collision>
        <visual name='Wall_2_Visual'>
          <pose frame=''>0 0 1.25 0 -0 0</pose>
          <geometry>
            <box>
              <size>8.15 0.15 2.5</size>
            </box>
          </geometry>
          <material>
            <script>
              <uri>file://media/materials/scripts/gazebo.material</uri>
              <name>Gazebo/Grey</name>
            </script>
            <ambient>1 1 1 1</ambient>
          </material>
          <meta>
            <layer>0</layer>
          </meta>
        </visual>
        <pose frame=''>0 -6 0 0 -0 0</pose>
        <self_collide>0</self_collide>
        <kinematic>0</kinematic>
      </link>
      <link name='Wall_3'>
        <collision name='Wall_3_Collision'>
          <geometry>
            <box>
              <size>2.97843 0.15 2.5</size>
            </box>
          </geometry>
          <pose frame=''>0 0 1.25 0 -0 0</pose>
          <max_contacts>10</max_contacts>
          <surface>
            <contact>
              <ode/>
            </contact>
            <bounce/>
            <friction>
              <torsional>
                <ode/>
              </torsional>
              <ode/>
            </friction>
          </surface>
        </collision>
        <visual name='Wall_3_Visual'>
          <pose frame=''>0 0 1.25 0 -0 0</pose>
          <geometry>
            <box>
              <size>2.97843 0.15 2.5</size>
            </box>
          </geometry>
          <material>
            <script>
              <uri>file://media/materials/scripts/gazebo.material</uri>
              <name>Gazebo/Grey</name>
            </script>
            <ambient>1 1 1 1</ambient>
          </material>
          <meta>
            <layer>0</layer>
          </meta>
        </visual>
        <pose frame=''>5 -5 0 0 -0 0.785398</pose>
        <self_collide>0</self_collide>
        <kinematic>0</kinematic>
      </link>
      <link name='Wall_4'>
        <collision name='Wall_4_Collision'>
          <geometry>
            <box>
              <size>8.15 0.15 2.5</size>
            </box>
          </geometry>
          <pose frame=''>0 0 1.25 0 -0 0</pose>
          <max_contacts>10</max_contacts>
          <surface>
            <contact>
              <ode/>
            </contact>
            <bounce/>
            <friction>
              <torsional>
                <ode/>
              </torsional>
              <ode/>
            </friction>
          </surface>
        </collision>
        <visual name='Wall_4_Visual'>
          <pose frame=''>0 0 1.25 0 -0 0</pose>
          <geometry>
            <box>
              <size>8.15 0.15 2.5</size>
            </box>
          </geometry>
          <material>
            <script>
              <uri>file://media/materials/scripts/gazebo.material</uri>
              <name>Gazebo/Grey</name>
            </script>
            <ambient>1 1 1 1</ambient>
          </material>
          <meta>
            <layer>0</layer>
          </meta>
        </visual>
        <pose frame=''>6 0 0 0 -0 1.5708</pose>
        <self_collide>0</self_collide>
        <kinematic>0</kinematic>
      </link>
      <link name='Wall_5'>
        <collision name='Wall_5_Collision'>
          <geometry>
            <box>
              <size>2.97843 0.15 2.5</size>
            </box>
          </geometry>
          <pose frame=''>0 0 1.25 0 -0 0</pose>
          <max_contacts>10</max_contacts>
          <surface>
            <contact>
              <ode/>
            </contact>
            <bounce/>
            <friction>
              <torsional>
                <ode/>
              </torsional>
              <ode/>
            </friction>
          </surface>
        </collision>
        <visual name='Wall_5_Visual'>
          <pose frame=''>0 0 1.25 0 -0 0</pose>
          <geometry>
            <box>
              <size>2.97843 0.15 2.5</size>
            </box>
          </geometry>
          <material>
            <script>
              <uri>file://media/materials/scripts/gazebo.material</uri>
              <name>Gazebo/Grey</name>
            </script>
            <ambient>1 1 1 1</ambient>
          </material>
          <meta>
            <layer>0</layer>
          </meta>
        </visual>
        <pose frame=''>5 5 0 0 -0 2.35619</pose>
        <self_collide>0</self_collide>
        <kinematic>0</kinematic>
      </link>
      <link name='Wall_6'>
        <collision name='Wall_6_Collision'>
          <geometry>
            <box>
              <size>8.15 0.15 2.5</size>
            </box>
          </geometry>
          <pose frame=''>0 0 1.25 0 -0 0</pose>
          <max_contacts>10</max_contacts>
          <surface>
            <contact>
              <ode/>
            </contact>
            <bounce/>
            <friction>
              <torsional>
                <ode/>
              </torsional>
              <ode/>
            </friction>
          </surface>
        </collision>
        <visual name='Wall_6_Visual'>
          <pose frame=''>0 0 1.25 0 -0 0</pose>
          <geometry>
            <box>
              <size>8.15 0.15 2.5</size>
            </box>
          </geometry>
          <material>
            <script>
              <uri>file://media/materials/scripts/gazebo.material</uri>
              <name>Gazebo/Grey</name>
            </script>
            <ambient>1 1 1 1</ambient>
          </material>
          <meta>
            <layer>0</layer>
          </meta>
        </visual>
        <pose frame=''>0 6 0 0 -0 3.14159</pose>
        <self_collide>0</self_collide>
        <kinematic>0</kinematic>
      </link>
      <link name='Wall_7'>
        <collision name='Wall_7_Collision'>
          <geometry>
            <box>
              <size>2.97843 0.15 2.5</size>
            </box>
          </geometry>
          <pose frame=''>0 0 1.25 0 -0 0</pose>
          <max_contacts>10</max_contacts>
          <surface>
            <contact>
              <ode/>
            </contact>
            <bounce/>
            <friction>
              <torsional>
                <ode/>
              </torsional>
              <ode/>
            </friction>
          </surface>
        </collision>
        <visual name='Wall_7_Visual'>
          <pose frame=''>0 0 1.25 0 -0 0</pose>
          <geometry>
            <box>
              <size>2.97843 0.15 2.5</size>
            </box>
          </geometry>
          <material>
            <script>
              <uri>file://media/materials/scripts/gazebo.material</uri>
              <name>Gazebo/Grey</name>
            </script>
            <ambient>1 1 1 1</ambient>
          </material>
          <meta>
            <layer>0</layer>
          </meta>
        </visual>
        <pose frame=''>-5 5 0 0 0 -2.35619</pose>
        <self_collide>0</self_collide>
        <kinematic>0</kinematic>
      </link>
      <link name='Wall_8'>
        <collision name='Wall_8_Collision'>
          <geometry>
            <box>
              <size>8.15 0.15 2.5</size>
            </box>
          </geometry>
          <pose frame=''>0 0 1.25 0 -0 0</pose>
          <max_contacts>10</max_contacts>
          <surface>
            <contact>
              <ode/>
            </contact>
            <bounce/>
            <friction>
              <torsional>
                <ode/>
              </torsional>
              <ode/>
            </friction>
          </surface>
        </collision>
        <visual name='Wall_8_Visual'>
          <pose frame=''>0 0 1.25 0 -0 0</pose>
          <geometry>
            <box>
              <size>8.15 0.15 2.5</size>
            </box>
          </geometry>
          <material>
            <script>
              <uri>file://media/materials/scripts/gazebo.material</uri>
              <name>Gazebo/Grey</name>
            </script>
            <ambient>1 1 1 1</ambient>
          </material>
          <meta>
            <layer>0</layer>
          </meta>
        </visual>
        <pose frame=''>-6 0 0 0 0 -1.5708</pose>
        <self_collide>0</self_collide>
        <kinematic>0</kinematic>
      </link>
      <link name='Wall_9'>
        <collision name='Wall_9_Collision'>
          <geometry>
            <box>
              <size>2.97843 0.15 2.5</size>
            </box>
          </geometry>
          <pose frame=''>0 0 1.25 0 -0 0</pose>
          <max_contacts>10</max_contacts>
          <surface>
            <contact>
              <ode/>
            </contact>
            <bounce/>
            <friction>
              <torsional>
                <ode/>
              </torsional>
              <ode/>
            </friction>
          </surface>
        </collision>
        <visual name='Wall_9_Visual'>
          <pose frame=''>0 0 1.25 0 -0 0</pose>
          <geometry>
            <box>
              <size>2.97843 0.15 2.5</size>
            </box>
          </geometry>
          <material>
            <script>
              <uri>file://media/materials/scripts/gazebo.material</uri>
              <name>Gazebo/Grey</name>
            </script>
            <ambient>1 1 1 1</ambient>
          </material>
          <meta>
            <layer>0</layer>
          </meta>
        </visual>
        <pose frame=''>-5 -5 0 0 0 -0.785398</pose>
        <self_collide>0</self_collide>
        <kinematic>0</kinematic>
      </link>
      <static>1</static>
    </model>
    <model name='turtlebot'>
      <plugin name='turtlebotplugin' filename='libturtlebotplugin.so'>
        <alwaysOn>1</alwaysOn>
        <updateRate>10.0</updateRate>
        <bodyName>rack</bodyName>
        <velocityXYLimit>3</velocityXYLimit>
        <velocityZLimit>5</velocityZLimit>
        <offset>0</offset>
        <drift>0.1</drift>
        <motionSmallNoise>0</motionSmallNoise>
        <motionDriftNoise>0</motionDriftNoise>
        <motionDriftNoiseTime>1.0</motionDriftNoiseTime>
        <rollpitchProportionalGain>10.0</rollpitchProportionalGain>
        <rollpitchDifferentialGain>5.0</rollpitchDifferentialGain>
        <rollpitchLimit>0.5</rollpitchLimit>
        <yawProportionalGain>2.0</yawProportionalGain>
        <yawDifferentialGain>1.0</yawDifferentialGain>
        <yawLimit>1.5</yawLimit>
        <left_joint>create::left_wheel</left_joint>
        <right_joint>create::right_wheel</right_joint>
        <velocityXYProportionalGain>5.0</velocityXYProportionalGain>
        <velocityXYDifferentialGain>1.0</velocityXYDifferentialGain>
        <velocityZProportionalGain>4.5</velocityZProportionalGain>
        <velocityZDifferentialGain>0.5</velocityZDifferentialGain>
        <velocityZIntegralGain>0.0</velocityZIntegralGain>
        <iceConfigFile>turtlebotplugin.cfg</iceConfigFile>
      </plugin>
      <link name='rack'>
        <inertial>
          <pose frame=''>0.001453 -0.000453 0.029787 0 -0 0</pose>
          <inertia>
            <ixx>0.05864</ixx>
            <ixy>0.000124</ixy>
            <ixz>0.000615</ixz>
            <iyy>0.058786</iyy>
            <iyz>1.4e-05</iyz>
            <izz>1.53244</izz>
          </inertia>
          <mass>2.234</mass>
        </inertial>
        <collision name='tag1_collision'>
          <pose frame=''>0 0 0.44 0 -0 0</pose>
          <geometry>
            <box>
              <size>0.4 0.2 0.01</size>
            </box>
          </geometry>
          <max_contacts>10</max_contacts>
          <surface>
            <contact>
              <ode/>
            </contact>
            <bounce/>
            <friction>
              <torsional>
                <ode/>
              </torsional>
              <ode/>
            </friction>
          </surface>
        </collision>
        <visual name='tag1_visual'>
          <pose frame=''>0 0 0.44 0 -0 0</pose>
          <cast_shadows>1</cast_shadows>
          <geometry>
            <box>
              <size>0.4 0.2 0.01</size>
            </box>
          </geometry>
          <material>
            <diffuse>0 1 0 1</diffuse>
          </material>
        </visual>
        <collision name='tag2_collision'>
          <pose frame=''>0.14 0 0.45 0 -0 0</pose>
          <geometry>
            <box>
              <size>0.12 0.2 0.01</size>
            </box>
          </geometry>
          <max_contacts>10</max_contacts>
          <surface>
            <contact>
              <ode/>
            </contact>
            <bounce/>
            <friction>
              <torsional>
                <ode/>
              </torsional>
              <ode/>
            </friction>
          </surface>
        </collision>
        <visual name='tag2_visual'>
          <pose frame=''>0.14 0 0.45 0 -0 0</pose>
          <cast_shadows>1</cast_shadows>
          <geometry>
            <box>
              <size>0.12 0.2 0.01</size>
            </box>
          </geometry>
          <material>
            <diffuse>0 0 1 1</diffuse>
          </material>
        </visual>
        <collision name='plate_0_collision'>
          <pose frame=''>-0.04334 0 0.084757 0 -0 0</pose>
          <geometry>
            <box>
              <size>0.233502 0.314845 0.006401</size>
            </box>
          </geometry>
          <max_contacts>10</max_contacts>
          <surface>
            <contact>
              <ode/>
            </contact>
            <bounce/>
            <friction>
              <torsional>
                <ode/>
              </torsional>
              <ode/>
            </friction>
          </surface>
        </collision>
        <visual name='plate_0_visual'>
          <pose frame=''>-0.04334 0 0.084757 0 -0 0</pose>
          <geometry>
            <mesh>
              <uri>model://turtlebotJde2cam/meshes/plate_0_logo.dae</uri>
            </mesh>
          </geometry>
        </visual>
        <collision name='plate_1_collision'>
          <pose frame=''>-0.00266 0 0.141907 0 -0 0</pose>
          <geometry>
            <box>
              <size>0.314856 0.314856 0.006401</size>
            </box>
          </geometry>
          <max_contacts>10</max_contacts>
          <surface>
            <contact>
              <ode/>
            </contact>
            <bounce/>
            <friction>
              <torsional>
                <ode/>
              </torsional>
              <ode/>
            </friction>
          </surface>
        </collision>
        <visual name='plate_1_visual'>
          <pose frame=''>-0.00266 0 0.141907 0 -0 0</pose>
          <geometry>
            <mesh>
              <uri>model://turtlebotJde2cam/meshes/plate_1_logo.dae</uri>
            </mesh>
          </geometry>
        </visual>
        <collision name='plate_2_collision'>
          <pose frame=''>-0.00266 0 0.199108 0 -0 0</pose>
          <geometry>
            <box>
              <size>0.314856 0.314856 0.006401</size>
            </box>
          </geometry>
          <max_contacts>10</max_contacts>
          <surface>
            <contact>
              <ode/>
            </contact>
            <bounce/>
            <friction>
              <torsional>
                <ode/>
              </torsional>
              <ode/>
            </friction>
          </surface>
        </collision>
        <visual name='plate_2_visual'>
          <pose frame=''>-0.00266 0 0.199108 0 -0 0</pose>
          <geometry>
            <mesh>
              <uri>model://turtlebotJde2cam/meshes/plate_1_logo.dae</uri>
            </mesh>
          </geometry>
        </visual>
        <collision name='plate_3_collision'>
          <pose frame=''>-0.01582 0 0.405457 0 -0 0</pose>
          <geometry>
            <box>
              <size>0.288 0.315 0.006401</size>
            </box>
          </geometry>
          <max_contacts>10</max_contacts>
          <surface>
            <contact>
              <ode/>
            </contact>
            <bounce/>
            <friction>
              <torsional>
                <ode/>
              </torsional>
              <ode/>
            </friction>
          </surface>
        </collision>
        <visual name='plate_3_visual'>
          <pose frame=''>-0.01582 0 0.405457 0 -0 0</pose>
          <geometry>
            <mesh>
              <uri>model://turtlebotJde2cam/meshes/plate_2_logo.dae</uri>
            </mesh>
          </geometry>
        </visual>
        <collision name='spacer_0_collision'>
          <pose frame=''>-0.00254 0.111468 0.079992 0 -0 0</pose>
          <geometry>
            <cylinder>
              <radius>0.0127</radius>
              <length>0.003175</length>
            </cylinder>
          </geometry>
          <max_contacts>10</max_contacts>
          <surface>
            <contact>
              <ode/>
            </contact>
            <bounce/>
            <friction>
              <torsional>
                <ode/>
              </torsional>
              <ode/>
            </friction>
          </surface>
        </collision>
        <visual name='spacer_0_visual'>
          <pose frame=''>-0.00254 0.111468 0.079992 0 -0 0</pose>
          <geometry>
            <mesh>
              <uri>model://turtlebotJde2cam/meshes/68-02403-125_Spacer.dae</uri>
            </mesh>
          </geometry>
        </visual>
        <collision name='spacer_1_collision'>
          <pose frame=''>-0.00254 -0.111468 0.079992 0 -0 0</pose>
          <geometry>
            <cylinder>
              <radius>0.0127</radius>
              <length>0.003175</length>
            </cylinder>
          </geometry>
          <max_contacts>10</max_contacts>
          <surface>
            <contact>
              <ode/>
            </contact>
            <bounce/>
            <friction>
              <torsional>
                <ode/>
              </torsional>
              <ode/>
            </friction>
          </surface>
        </collision>
        <visual name='spacer_1_visual'>
          <pose frame=''>-0.00254 -0.111468 0.079992 0 -0 0</pose>
          <geometry>
            <mesh>
              <uri>model://turtlebotJde2cam/meshes/68-02403-125_Spacer.dae</uri>
            </mesh>
          </geometry>
        </visual>
        <collision name='spacer_2_collision'>
          <pose frame=''>-0.07239 -0.111468 0.079992 0 -0 0</pose>
          <geometry>
            <cylinder>
              <radius>0.0127</radius>
              <length>0.003175</length>
            </cylinder>
          </geometry>
          <max_contacts>10</max_contacts>
          <surface>
            <contact>
              <ode/>
            </contact>
            <bounce/>
            <friction>
              <torsional>
                <ode/>
              </torsional>
              <ode/>
            </friction>
          </surface>
        </collision>
        <visual name='spacer_2_visual'>
          <pose frame=''>-0.07239 -0.111468 0.079992 0 -0 0</pose>
          <geometry>
            <mesh>
              <uri>model://turtlebotJde2cam/meshes/68-02403-125_Spacer.dae</uri>
            </mesh>
          </geometry>
        </visual>
        <collision name='spacer_3_collision'>
          <pose frame=''>-0.07239 0.111468 0.079992 0 -0 0</pose>
          <geometry>
            <cylinder>
              <radius>0.0127</radius>
              <length>0.003175</length>
            </cylinder>
          </geometry>
          <max_contacts>10</max_contacts>
          <surface>
            <contact>
              <ode/>
            </contact>
            <bounce/>
            <friction>
              <torsional>
                <ode/>
              </torsional>
              <ode/>
            </friction>
          </surface>
        </collision>
        <visual name='spacer_3_visual'>
          <pose frame=''>-0.07239 0.111468 0.079992 0 -0 0</pose>
          <geometry>
            <mesh>
              <uri>model://turtlebotJde2cam/meshes/68-02403-125_Spacer.dae</uri>
            </mesh>
          </geometry>
        </visual>
        <collision name='standoff_2in_0_collision'>
          <pose frame=''>0.06764 0.13142 0.08798 0 -0 0</pose>
          <geometry>
            <cylinder>
              <radius>0.0381</radius>
              <length>0.0635</length>
            </cylinder>
          </geometry>
          <max_contacts>10</max_contacts>
          <surface>
            <contact>
              <ode/>
            </contact>
            <bounce/>
            <friction>
              <torsional>
                <ode/>
              </torsional>
              <ode/>
            </friction>
          </surface>
        </collision>
        <visual name='standoff_2in_0_visual'>
          <pose frame=''>0.06764 0.13142 0.08798 0 -0 0</pose>
          <geometry>
            <mesh>
              <uri>model://turtlebotJde2cam/meshes/68-04552-2000-RA_Turtlebot_M-F_Standoff.dae</uri>
            </mesh>
          </geometry>
        </visual>
        <collision name='standoff_2in_1_collision'>
          <pose frame=''>0.06764 -0.13142 0.08798 0 -0 0</pose>
          <geometry>
            <cylinder>
              <radius>0.0381</radius>
              <length>0.0635</length>
            </cylinder>
          </geometry>
          <max_contacts>10</max_contacts>
          <surface>
            <contact>
              <ode/>
            </contact>
            <bounce/>
            <friction>
              <torsional>
                <ode/>
              </torsional>
              <ode/>
            </friction>
          </surface>
        </collision>
        <visual name='standoff_2in_1_visual'>
          <pose frame=''>0.06764 -0.13142 0.08798 0 -0 0</pose>
          <geometry>
            <mesh>
              <uri>model://turtlebotJde2cam/meshes/68-04552-2000-RA_Turtlebot_M-F_Standoff.dae</uri>
            </mesh>
          </geometry>
        </visual>
        <collision name='standoff_2in_2_collision'>
          <pose frame=''>-0.052832 -0.13142 0.08798 0 -0 0</pose>
          <geometry>
            <cylinder>
              <radius>0.0381</radius>
              <length>0.0635</length>
            </cylinder>
          </geometry>
          <max_contacts>10</max_contacts>
          <surface>
            <contact>
              <ode/>
            </contact>
            <bounce/>
            <friction>
              <torsional>
                <ode/>
              </torsional>
              <ode/>
            </friction>
          </surface>
        </collision>
        <visual name='standoff_2in_2_visual'>
          <pose frame=''>-0.052832 -0.13142 0.08798 0 -0 0</pose>
          <geometry>
            <mesh>
              <uri>model://turtlebotJde2cam/meshes/68-04552-2000-RA_Turtlebot_M-F_Standoff.dae</uri>
            </mesh>
          </geometry>
        </visual>
        <collision name='standoff_2in_3_collision'>
          <pose frame=''>-0.052832 0.13142 0.08798 0 -0 0</pose>
          <geometry>
            <cylinder>
              <radius>0.0381</radius>
              <length>0.0635</length>
            </cylinder>
          </geometry>
          <max_contacts>10</max_contacts>
          <surface>
            <contact>
              <ode/>
            </contact>
            <bounce/>
            <friction>
              <torsional>
                <ode/>
              </torsional>
              <ode/>
            </friction>
          </surface>
        </collision>
        <visual name='standoff_2in_3_visual'>
          <pose frame=''>-0.052832 0.13142 0.08798 0 -0 0</pose>
          <geometry>
            <mesh>
              <uri>model://turtlebotJde2cam/meshes/68-04552-2000-RA_Turtlebot_M-F_Standoff.dae</uri>
            </mesh>
          </geometry>
        </visual>
        <collision name='standoff_2in_4_collision'>
          <pose frame=''>0.06764 0.13142 0.14513 0 -0 0</pose>
          <geometry>
            <cylinder>
              <radius>0.0381</radius>
              <length>0.0635</length>
            </cylinder>
          </geometry>
          <max_contacts>10</max_contacts>
          <surface>
            <contact>
              <ode/>
            </contact>
            <bounce/>
            <friction>
              <torsional>
                <ode/>
              </torsional>
              <ode/>
            </friction>
          </surface>
        </collision>
        <visual name='standoff_2in_4_visual'>
          <pose frame=''>0.06764 0.13142 0.14513 0 -0 0</pose>
          <geometry>
            <mesh>
              <uri>model://turtlebotJde2cam/meshes/68-04552-2000-RA_Turtlebot_M-F_Standoff.dae</uri>
            </mesh>
          </geometry>
        </visual>
        <collision name='standoff_2in_5_collision'>
          <pose frame=''>0.06764 -0.13142 0.14513 0 -0 0</pose>
          <geometry>
            <cylinder>
              <radius>0.0381</radius>
              <length>0.0635</length>
            </cylinder>
          </geometry>
          <max_contacts>10</max_contacts>
          <surface>
            <contact>
              <ode/>
            </contact>
            <bounce/>
            <friction>
              <torsional>
                <ode/>
              </torsional>
              <ode/>
            </friction>
          </surface>
        </collision>
        <visual name='standoff_2in_5_visual'>
          <pose frame=''>0.06764 -0.13142 0.14513 0 -0 0</pose>
          <geometry>
            <mesh>
              <uri>model://turtlebotJde2cam/meshes/68-04552-2000-RA_Turtlebot_M-F_Standoff.dae</uri>
            </mesh>
          </geometry>
        </visual>
        <collision name='standoff_2in_6_collision'>
          <pose frame=''>-0.052832 -0.13142 0.14513 0 -0 0</pose>
          <geometry>
            <cylinder>
              <radius>0.0381</radius>
              <length>0.0635</length>
            </cylinder>
          </geometry>
          <max_contacts>10</max_contacts>
          <surface>
            <contact>
              <ode/>
            </contact>
            <bounce/>
            <friction>
              <torsional>
                <ode/>
              </torsional>
              <ode/>
            </friction>
          </surface>
        </collision>
        <visual name='standoff_2in_6_visual'>
          <pose frame=''>-0.052832 -0.13142 0.14513 0 -0 0</pose>
          <geometry>
            <mesh>
              <uri>model://turtlebotJde2cam/meshes/68-04552-2000-RA_Turtlebot_M-F_Standoff.dae</uri>
            </mesh>
          </geometry>
        </visual>
        <collision name='standoff_2in_7_collision'>
          <pose frame=''>-0.052832 0.13142 0.14513 0 -0 0</pose>
          <geometry>
            <cylinder>
              <radius>0.0381</radius>
              <length>0.0635</length>
            </cylinder>
          </geometry>
          <max_contacts>10</max_contacts>
          <surface>
            <contact>
              <ode/>
            </contact>
            <bounce/>
            <friction>
              <torsional>
                <ode/>
              </torsional>
              <ode/>
            </friction>
          </surface>
        </collision>
        <visual name='standoff_2in_7_visual'>
          <pose frame=''>-0.052832 0.13142 0.14513 0 -0 0</pose>
          <geometry>
            <mesh>
              <uri>model://turtlebotJde2cam/meshes/68-04552-2000-RA_Turtlebot_M-F_Standoff.dae</uri>
            </mesh>
          </geometry>
        </visual>
        <collision name='standoff_8in_0_collision'>
          <pose frame=''>0.06764 0.13142 0.20228 0 -0 0</pose>
          <geometry>
            <cylinder>
              <radius>0.011113</radius>
              <length>0.2032</length>
            </cylinder>
          </geometry>
          <max_contacts>10</max_contacts>
          <surface>
            <contact>
              <ode/>
            </contact>
            <bounce/>
            <friction>
              <torsional>
                <ode/>
              </torsional>
              <ode/>
            </friction>
          </surface>
        </collision>
        <visual name='standoff_8in_0_visual'>
          <pose frame=''>0.06764 0.13142 0.20228 0 -0 0</pose>
          <geometry>
            <mesh>
              <uri>model://turtlebotJde2cam/meshes/68-02421-8000-RA_Turtlebot_F-F_Standoff.dae</uri>
            </mesh>
          </geometry>
        </visual>
        <collision name='standoff_8in_1_collision'>
          <pose frame=''>0.06764 -0.13142 0.20228 0 -0 0</pose>
          <geometry>
            <cylinder>
              <radius>0.011113</radius>
              <length>0.2032</length>
            </cylinder>
          </geometry>
          <max_contacts>10</max_contacts>
          <surface>
            <contact>
              <ode/>
            </contact>
            <bounce/>
            <friction>
              <torsional>
                <ode/>
              </torsional>
              <ode/>
            </friction>
          </surface>
        </collision>
        <visual name='standoff_8in_1_visual'>
          <pose frame=''>0.06764 -0.13142 0.20228 0 -0 0</pose>
          <geometry>
            <mesh>
              <uri>model://turtlebotJde2cam/meshes/68-02421-8000-RA_Turtlebot_F-F_Standoff.dae</uri>
            </mesh>
          </geometry>
        </visual>
        <collision name='standoff_8in_2_collision'>
          <pose frame=''>-0.052832 -0.13142 0.20228 0 -0 0</pose>
          <geometry>
            <cylinder>
              <radius>0.011113</radius>
              <length>0.2032</length>
            </cylinder>
          </geometry>
          <max_contacts>10</max_contacts>
          <surface>
            <contact>
              <ode/>
            </contact>
            <bounce/>
            <friction>
              <torsional>
                <ode/>
              </torsional>
              <ode/>
            </friction>
          </surface>
        </collision>
        <visual name='standoff_8in_2_visual'>
          <pose frame=''>-0.052832 -0.13142 0.20228 0 -0 0</pose>
          <geometry>
            <mesh>
              <uri>model://turtlebotJde2cam/meshes/68-02421-8000-RA_Turtlebot_F-F_Standoff.dae</uri>
            </mesh>
          </geometry>
        </visual>
        <collision name='standoff_8in_3_collision'>
          <pose frame=''>-0.052832 0.13142 0.20228 0 -0 0</pose>
          <geometry>
            <cylinder>
              <radius>0.011113</radius>
              <length>0.2032</length>
            </cylinder>
          </geometry>
          <max_contacts>10</max_contacts>
          <surface>
            <contact>
              <ode/>
            </contact>
            <bounce/>
            <friction>
              <torsional>
                <ode/>
              </torsional>
              <ode/>
            </friction>
          </surface>
        </collision>
        <visual name='standoff_8in_3_visual'>
          <pose frame=''>-0.052832 0.13142 0.20228 0 -0 0</pose>
          <geometry>
            <mesh>
              <uri>model://turtlebotJde2cam/meshes/68-02421-8000-RA_Turtlebot_F-F_Standoff.dae</uri>
            </mesh>
          </geometry>
        </visual>
        <collision name='standoff_kinect_0_collision'>
          <pose frame=''>-0.105098 0.098 0.202308 0 -0 0</pose>
          <geometry>
            <cylinder>
              <radius>0.001111</radius>
              <length>0.008585</length>
            </cylinder>
          </geometry>
          <max_contacts>10</max_contacts>
          <surface>
            <contact>
              <ode/>
            </contact>
            <bounce/>
            <friction>
              <torsional>
                <ode/>
              </torsional>
              <ode/>
            </friction>
          </surface>
        </collision>
        <visual name='standoff_kinect_0_visual'>
          <pose frame=''>-0.105098 0.098 0.202308 0 -0 0</pose>
          <geometry>
            <mesh>
              <uri>model://turtlebotJde2cam/meshes/68-04556-RA_Kinect_Standoff_Assy.dae</uri>
            </mesh>
          </geometry>
        </visual>
        <collision name='standoff_kinect_1_collision'>
          <pose frame=''>-0.105098 -0.098 0.202308 0 -0 0</pose>
          <geometry>
            <cylinder>
              <radius>0.001111</radius>
              <length>0.008585</length>
            </cylinder>
          </geometry>
          <max_contacts>10</max_contacts>
          <surface>
            <contact>
              <ode/>
            </contact>
            <bounce/>
            <friction>
              <torsional>
                <ode/>
              </torsional>
              <ode/>
            </friction>
          </surface>
        </collision>
        <visual name='standoff_kinect_1_visual'>
          <pose frame=''>-0.105098 -0.098 0.202308 0 -0 0</pose>
          <geometry>
            <mesh>
              <uri>model://turtlebotJde2cam/meshes/68-04556-RA_Kinect_Standoff_Assy.dae</uri>
            </mesh>
          </geometry>
        </visual>
        <self_collide>0</self_collide>
        <kinematic>0</kinematic>
      </link>
      <link name='laser'>
        <pose frame=''>0.155 0 0.112 0 -0 0</pose>
        <gravity>0</gravity>
        <inertial>
          <mass>0.1</mass>
          <inertia>
            <ixx>1</ixx>
            <ixy>0</ixy>
            <ixz>0</ixz>
            <iyy>1</iyy>
            <iyz>0</iyz>
            <izz>1</izz>
          </inertia>
        </inertial>
        <visual name='visual'>
          <geometry>
            <mesh>
              <uri>model://hokuyo/meshes/hokuyo.dae</uri>
            </mesh>
          </geometry>
        </visual>
        <collision name='collision-base'>
          <pose frame=''>0 0 -0.0145 0 -0 0</pose>
          <geometry>
            <box>
              <size>0.05 0.05 0.041</size>
            </box>
          </geometry>
          <max_contacts>10</max_contacts>
          <surface>
            <bounce/>
            <friction>
              <ode/>
              <torsional>
                <ode/>
              </torsional>
            </friction>
            <contact>
              <ode/>
            </contact>
          </surface>
        </collision>
        <collision name='collision-top'>
          <pose frame=''>0 0 0.0205 0 -0 0</pose>
          <geometry>
            <cylinder>
              <radius>0.021</radius>
              <length>0.029</length>
            </cylinder>
          </geometry>
          <max_contacts>10</max_contacts>
          <surface>
            <bounce/>
            <friction>
              <ode/>
              <torsional>
                <ode/>
              </torsional>
            </friction>
            <contact>
              <ode/>
            </contact>
          </surface>
        </collision>
        <sensor name='laser' type='ray'>
          <ray>
            <scan>
              <horizontal>
                <samples>180</samples>
                <resolution>1</resolution>
                <min_angle>-1.57</min_angle>
                <max_angle>1.57</max_angle>
              </horizontal>
              <vertical>
                <samples>1</samples>
                <min_angle>0</min_angle>
                <max_angle>0</max_angle>
              </vertical>
            </scan>
            <range>
              <min>0.08</min>
              <max>10</max>
              <resolution>0.01</resolution>
            </range>
          </ray>
          <update_rate>20</update_rate>
          <always_on>1</always_on>
          <visualize>1</visualize>
        </sensor>
        <velocity_decay>
          <linear>0</linear>
          <angular>0</angular>
        </velocity_decay>
        <self_collide>0</self_collide>
        <kinematic>0</kinematic>
      </link>
      <link name='camera_bottom_body_left'>
        <pose frame=''>-0.03 0.076 0.2324 -1.57 0 0</pose>
        <inertial>
          <mass>0.5</mass>
          <inertia>
            <ixx>1</ixx>
            <ixy>0</ixy>
            <ixz>0</ixz>
            <iyy>1</iyy>
            <iyz>0</iyz>
            <izz>1</izz>
          </inertia>
        </inertial>
        <visual name='visual'>
          <geometry>
            <mesh>
              <uri>model://turtlebotJde2cam/meshes/sonyvid30/sonyvid30_bottom.dae</uri>
              <scale>4 3 3</scale>
            </mesh>
          </geometry>
        </visual>
        <collision name='collision'>
          <geometry>
            <box>
              <size>0.1 0.1 0.1</size>
            </box>
          </geometry>
          <surface>
            <friction>
              <ode>
                <mu>100000</mu>
                <mu2>100000</mu2>
                <slip1>0</slip1>
                <slip2>0</slip2>
              </ode>
              <torsional>
                <ode/>
              </torsional>
            </friction>
            <bounce/>
            <contact>
              <ode/>
            </contact>
          </surface>
          <max_contacts>10</max_contacts>
        </collision>
        <velocity_decay>
          <linear>0</linear>
          <angular>0</angular>
        </velocity_decay>
        <self_collide>0</self_collide>
        <kinematic>0</kinematic>
        <gravity>1</gravity>
      </link>
      <link name='camera_column_body_left'>
        <pose frame=''>-0.02 0.076 0.2474 -1.57 0 0</pose>
        <inertial>
          <mass>0.5</mass>
          <inertia>
            <ixx>1</ixx>
            <ixy>0</ixy>
            <ixz>0</ixz>
            <iyy>1</iyy>
            <iyz>0</iyz>
            <izz>1</izz>
          </inertia>
        </inertial>
        <visual name='visual'>
          <geometry>
            <mesh>
              <uri>model://turtlebotJde2cam/meshes/sonyvid30/sonyvid30_mid.dae</uri>
              <scale>0.6 1 1</scale>
            </mesh>
          </geometry>
        </visual>
        <collision name='collision'>
          <geometry>
            <box>
              <size>0.1 0.1 0.1</size>
            </box>
          </geometry>
          <surface>
            <friction>
              <ode>
                <mu>100000</mu>
                <mu2>100000</mu2>
                <slip1>0</slip1>
                <slip2>0</slip2>
              </ode>
              <torsional>
                <ode/>
              </torsional>
            </friction>
            <bounce/>
            <contact>
              <ode/>
            </contact>
          </surface>
          <max_contacts>10</max_contacts>
        </collision>
        <velocity_decay>
          <linear>0</linear>
          <angular>0</angular>
        </velocity_decay>
        <self_collide>0</self_collide>
        <kinematic>0</kinematic>
        <gravity>1</gravity>
      </link>
      <link name='camera_top_body_left'>
        <pose frame=''>-0.05 0.076 0.2424 -1.57 -0 3.14</pose>
        <inertial>
          <mass>0.5</mass>
          <inertia>
            <ixx>1</ixx>
            <ixy>0</ixy>
            <ixz>0</ixz>
            <iyy>1</iyy>
            <iyz>0</iyz>
            <izz>1</izz>
          </inertia>
        </inertial>
        <sensor name='cam_turtlebot_left' type='camera'>
          <pose frame=''>0 0 0 -1.57 -0 3.14</pose>
          <update_rate>20</update_rate>
          <camera name='__default__'>
            <horizontal_fov>1.57</horizontal_fov>
            <image>
              <width>640</width>
              <height>480</height>
              <format>R8G8B8</format>
            </image>
            <clip>
              <near>0.3</near>
              <far>15</far>
            </clip>
          </camera>
        </sensor>
        <visual name='visual'>
          <geometry>
            <mesh>
              <uri>model://turtlebotJde2cam/meshes/sonyvid30/sonyvid30_top.dae</uri>
              <scale>2 2 1.3</scale>
            </mesh>
          </geometry>
        </visual>
        <collision name='collision'>
          <geometry>
            <box>
              <size>0.1 0.1 0.1</size>
            </box>
          </geometry>
          <surface>
            <friction>
              <ode>
                <mu>100000</mu>
                <mu2>100000</mu2>
                <slip1>0</slip1>
                <slip2>0</slip2>
              </ode>
              <torsional>
                <ode/>
              </torsional>
            </friction>
            <bounce/>
            <contact>
              <ode/>
            </contact>
          </surface>
          <max_contacts>10</max_contacts>
        </collision>
        <velocity_decay>
          <linear>0</linear>
          <angular>0</angular>
        </velocity_decay>
        <self_collide>0</self_collide>
        <kinematic>0</kinematic>
        <gravity>1</gravity>
      </link>
      <link name='camera_bottom_body_right'>
        <pose frame=''>-0.03 -0.076 0.2324 -1.57 0 0</pose>
        <inertial>
          <mass>0.5</mass>
          <inertia>
            <ixx>1</ixx>
            <ixy>0</ixy>
            <ixz>0</ixz>
            <iyy>1</iyy>
            <iyz>0</iyz>
            <izz>1</izz>
          </inertia>
        </inertial>
        <visual name='visual'>
          <geometry>
            <mesh>
              <uri>model://turtlebotJde2cam/meshes/sonyvid30/sonyvid30_bottom.dae</uri>
              <scale>4 3 3</scale>
            </mesh>
          </geometry>
        </visual>
        <collision name='collision'>
          <geometry>
            <box>
              <size>0.1 0.1 0.1</size>
            </box>
          </geometry>
          <surface>
            <friction>
              <ode>
                <mu>100000</mu>
                <mu2>100000</mu2>
                <slip1>0</slip1>
                <slip2>0</slip2>
              </ode>
              <torsional>
                <ode/>
              </torsional>
            </friction>
            <bounce/>
            <contact>
              <ode/>
            </contact>
          </surface>
          <max_contacts>10</max_contacts>
        </collision>
        <velocity_decay>
          <linear>0</linear>
          <angular>0</angular>
        </velocity_decay>
        <self_collide>0</self_collide>
        <kinematic>0</kinematic>
        <gravity>1</gravity>
      </link>
      <link name='camera_column_body_right'>
        <pose frame=''>-0.02 -0.076 0.2474 -1.57 0 0</pose>
        <inertial>
          <mass>0.5</mass>
          <inertia>
            <ixx>1</ixx>
            <ixy>0</ixy>
            <ixz>0</ixz>
            <iyy>1</iyy>
            <iyz>0</iyz>
            <izz>1</izz>
          </inertia>
        </inertial>
        <visual name='visual'>
          <geometry>
            <mesh>
              <uri>model://turtlebotJde2cam/meshes/sonyvid30/sonyvid30_mid.dae</uri>
              <scale>0.6 1 1</scale>
            </mesh>
          </geometry>
        </visual>
        <collision name='collision'>
          <geometry>
            <box>
              <size>0.1 0.1 0.1</size>
            </box>
          </geometry>
          <surface>
            <friction>
              <ode>
                <mu>100000</mu>
                <mu2>100000</mu2>
                <slip1>0</slip1>
                <slip2>0</slip2>
              </ode>
              <torsional>
                <ode/>
              </torsional>
            </friction>
            <bounce/>
            <contact>
              <ode/>
            </contact>
          </surface>
          <max_contacts>10</max_contacts>
        </collision>
        <velocity_decay>
          <linear>0</linear>
          <angular>0</angular>
        </velocity_decay>
        <self_collide>0</self_collide>
        <kinematic>0</kinematic>
        <gravity>1</gravity>
      </link>
      <link name='camera_top_body_right'>
        <pose frame=''>-0.05 -0.076 0.2424 -1.57 -0 3.14</pose>
        <inertial>
          <mass>0.5</mass>
          <inertia>
            <ixx>1</ixx>
            <ixy>0</ixy>
            <ixz>0</ixz>
            <iyy>1</iyy>
            <iyz>0</iyz>
            <izz>1</izz>
          </inertia>
        </inertial>
        <sensor name='cam_turtlebot_right' type='camera'>
          <pose frame=''>0 0 0 -1.57 -0 3.14</pose>
          <update_rate>20</update_rate>
          <camera name='__default__'>
            <horizontal_fov>1.57</horizontal_fov>
            <image>
              <width>640</width>
              <height>480</height>
              <format>R8G8B8</format>
            </image>
            <clip>
              <near>0.3</near>
              <far>15</far>
            </clip>
          </camera>
        </sensor>
        <visual name='visual'>
          <geometry>
            <mesh>
              <uri>model://turtlebotJde2cam/meshes/sonyvid30/sonyvid30_top.dae</uri>
              <scale>2 2 1.3</scale>
            </mesh>
          </geometry>
        </visual>
        <collision name='collision'>
          <geometry>
            <box>
              <size>0.1 0.1 0.1</size>
            </box>
          </geometry>
          <surface>
            <friction>
              <ode>
                <mu>100000</mu>
                <mu2>100000</mu2>
                <slip1>0</slip1>
                <slip2>0</slip2>
              </ode>
              <torsional>
                <ode/>
              </torsional>
            </friction>
            <bounce/>
            <contact>
              <ode/>
            </contact>
          </surface>
          <max_contacts>10</max_contacts>
        </collision>
        <velocity_decay>
          <linear>0</linear>
          <angular>0</angular>
        </velocity_decay>
        <self_collide>0</self_collide>
        <kinematic>0</kinematic>
        <gravity>1</gravity>
      </link>
      <link name='create::base'>
        <inertial>
          <pose frame=''>0.001453 -0.000453 0.029787 0 -0 0</pose>
          <inertia>
            <ixx>0.05864</ixx>
            <ixy>0.000124</ixy>
            <ixz>0.000615</ixz>
            <iyy>0.058786</iyy>
            <iyz>1.4e-05</iyz>
            <izz>1.53244</izz>
          </inertia>
          <mass>2.234</mass>
        </inertial>
        <collision name='base_collision'>
          <pose frame=''>0 0 0.0478 0 -0 0</pose>
          <geometry>
            <mesh>
              <uri>model://create/meshes/create_body.dae</uri>
            </mesh>
          </geometry>
          <max_contacts>10</max_contacts>
          <surface>
            <contact>
              <ode/>
            </contact>
            <bounce/>
            <friction>
              <torsional>
                <ode/>
              </torsional>
              <ode/>
            </friction>
          </surface>
        </collision>
        <visual name='base_visual'>
          <pose frame=''>0 0 0.0478 0 -0 0</pose>
          <geometry>
            <mesh>
              <uri>model://create/meshes/create_body.dae</uri>
            </mesh>
          </geometry>
        </visual>
        <collision name='front_wheel_collision'>
          <pose frame=''>0.13 0 0.017 -0 1.5707 1.5707</pose>
          <geometry>
            <sphere>
              <radius>0.018</radius>
            </sphere>
          </geometry>
          <surface>
            <friction>
              <ode>
                <mu>0</mu>
                <mu2>0</mu2>
                <fdir1>0 0 0</fdir1>
                <slip1>0</slip1>
                <slip2>0</slip2>
              </ode>
              <torsional>
                <ode/>
              </torsional>
            </friction>
            <contact>
              <ode/>
            </contact>
            <bounce/>
          </surface>
          <max_contacts>10</max_contacts>
        </collision>
        <visual name='front_wheel_visual'>
          <pose frame=''>0.13 0 0.017 -0 1.5707 1.5707</pose>
          <geometry>
            <sphere>
              <radius>0.009</radius>
            </sphere>
          </geometry>
        </visual>
        <collision name='rear_wheel_collision'>
          <pose frame=''>-0.13 0 0.017 -0 1.5707 1.5707</pose>
          <geometry>
            <sphere>
              <radius>0.015</radius>
            </sphere>
          </geometry>
          <surface>
            <friction>
              <ode>
                <mu>0</mu>
                <mu2>0</mu2>
                <fdir1>0 0 0</fdir1>
                <slip1>0</slip1>
                <slip2>0</slip2>
              </ode>
              <torsional>
                <ode/>
              </torsional>
            </friction>
            <contact>
              <ode/>
            </contact>
            <bounce/>
          </surface>
          <max_contacts>10</max_contacts>
        </collision>
        <visual name='rear_wheel_visual'>
          <pose frame=''>-0.13 0 0.017 -0 1.5707 1.5707</pose>
          <geometry>
            <sphere>
              <radius>0.0075</radius>
            </sphere>
          </geometry>
        </visual>
        <sensor name='bumper' type='contact'>
          <contact>
            <collision>base_collision</collision>
            <topic>__default_topic__</topic>
          </contact>
        </sensor>
        <sensor name='left_cliff_sensor' type='ray'>
          <pose frame=''>0.07 0.14 0.027 0 1.57079 0</pose>
          <ray>
            <scan>
              <horizontal>
                <samples>1</samples>
                <resolution>1</resolution>
                <min_angle>0</min_angle>
                <max_angle>0</max_angle>
              </horizontal>
              <vertical>
                <samples>1</samples>
                <min_angle>0</min_angle>
                <max_angle>0</max_angle>
              </vertical>
            </scan>
            <range>
              <min>0.01</min>
              <max>0.04</max>
              <resolution>0.1</resolution>
            </range>
          </ray>
        </sensor>
        <sensor name='leftfront_cliff_sensor' type='ray'>
          <pose frame=''>0.15 0.04 0.027 0 1.57079 0</pose>
          <ray>
            <scan>
              <horizontal>
                <samples>1</samples>
                <resolution>1</resolution>
                <min_angle>0</min_angle>
                <max_angle>0</max_angle>
              </horizontal>
              <vertical>
                <samples>1</samples>
                <min_angle>0</min_angle>
                <max_angle>0</max_angle>
              </vertical>
            </scan>
            <range>
              <min>0.01</min>
              <max>0.04</max>
              <resolution>0.1</resolution>
            </range>
          </ray>
        </sensor>
        <sensor name='right_cliff_sensor' type='ray'>
          <pose frame=''>0.07 -0.14 0.027 0 1.57079 0</pose>
          <ray>
            <scan>
              <horizontal>
                <samples>1</samples>
                <resolution>1</resolution>
                <min_angle>0</min_angle>
                <max_angle>0</max_angle>
              </horizontal>
              <vertical>
                <samples>1</samples>
                <min_angle>0</min_angle>
                <max_angle>0</max_angle>
              </vertical>
            </scan>
            <range>
              <min>0.01</min>
              <max>0.04</max>
              <resolution>0.1</resolution>
            </range>
          </ray>
        </sensor>
        <sensor name='rightfront_cliff_sensor' type='ray'>
          <pose frame=''>0.15 -0.04 0.027 0 1.57079 0</pose>
          <ray>
            <scan>
              <horizontal>
                <samples>1</samples>
                <resolution>1</resolution>
                <min_angle>0</min_angle>
                <max_angle>0</max_angle>
              </horizontal>
              <vertical>
                <samples>1</samples>
                <min_angle>0</min_angle>
                <max_angle>0</max_angle>
              </vertical>
            </scan>
            <range>
              <min>0.01</min>
              <max>0.04</max>
              <resolution>0.1</resolution>
            </range>
          </ray>
        </sensor>
        <sensor name='wall_sensor' type='ray'>
          <pose frame=''>0.09 -0.12 0.059 0 0 -1</pose>
          <ray>
            <scan>
              <horizontal>
                <samples>1</samples>
                <resolution>1</resolution>
                <min_angle>0</min_angle>
                <max_angle>0</max_angle>
              </horizontal>
              <vertical>
                <samples>1</samples>
                <min_angle>0</min_angle>
                <max_angle>0</max_angle>
              </vertical>
            </scan>
            <range>
              <min>0.016</min>
              <max>0.04</max>
              <resolution>0.1</resolution>
            </range>
          </ray>
        </sensor>
        <pose frame=''>0 0 0 0 -0 0</pose>
        <self_collide>0</self_collide>
        <kinematic>0</kinematic>
      </link>
      <link name='create::left_wheel'>
        <pose frame=''>0 0.13 0.032 0 -0 0</pose>
        <inertial>
          <inertia>
            <ixx>0.001</ixx>
            <ixy>0</ixy>
            <ixz>0</ixz>
            <iyy>0.001</iyy>
            <iyz>0</iyz>
            <izz>0.001</izz>
          </inertia>
          <mass>0.01</mass>
        </inertial>
        <collision name='collision'>
          <pose frame=''>0 0 0 -0 1.5707 1.5707</pose>
          <geometry>
            <cylinder>
              <radius>0.033</radius>
              <length>0.023</length>
            </cylinder>
          </geometry>
          <surface>
            <friction>
              <ode>
                <mu>10</mu>
                <mu2>10</mu2>
                <fdir1>0 0 0</fdir1>
                <slip1>0</slip1>
                <slip2>0</slip2>
              </ode>
              <torsional>
                <ode/>
              </torsional>
            </friction>
            <contact>
              <ode/>
            </contact>
            <bounce/>
          </surface>
          <max_contacts>10</max_contacts>
        </collision>
        <visual name='visual'>
          <pose frame=''>0 0 0 -0 1.5707 1.5707</pose>
          <geometry>
            <cylinder>
              <radius>0.033</radius>
              <length>0.023</length>
            </cylinder>
          </geometry>
        </visual>
        <self_collide>0</self_collide>
        <kinematic>0</kinematic>
      </link>
      <link name='create::right_wheel'>
        <pose frame=''>0 -0.13 0.032 0 -0 0</pose>
        <inertial>
          <inertia>
            <ixx>0.001</ixx>
            <ixy>0</ixy>
            <ixz>0</ixz>
            <iyy>0.001</iyy>
            <iyz>0</iyz>
            <izz>0.001</izz>
          </inertia>
          <mass>0.01</mass>
        </inertial>
        <collision name='collision'>
          <pose frame=''>0 0 0 -0 1.5707 1.5707</pose>
          <geometry>
            <cylinder>
              <radius>0.033</radius>
              <length>0.023</length>
            </cylinder>
          </geometry>
          <surface>
            <friction>
              <ode>
                <mu>10</mu>
                <mu2>10</mu2>
                <fdir1>0 0 0</fdir1>
                <slip1>0</slip1>
                <slip2>0</slip2>
              </ode>
              <torsional>
                <ode/>
              </torsional>
            </friction>
            <contact>
              <ode/>
            </contact>
            <bounce/>
          </surface>
          <max_contacts>10</max_contacts>
        </collision>
        <visual name='visual'>
          <pose frame=''>0 0 0 -0 1.5707 1.5707</pose>
          <geometry>
            <cylinder>
              <radius>0.033</radius>
              <length>0.023</length>
            </cylinder>
          </geometry>
        </visual>
        <self_collide>0</self_collide>
        <kinematic>0</kinematic>
      </link>
      <joint name='create::left_wheel' type='revolute'>
        <parent>create::base</parent>
        <child>create::left_wheel</child>
        <axis>
          <xyz>0 1 0</xyz>
          <use_parent_model_frame>1</use_parent_model_frame>
          <limit>
            <lower>-1e+16</lower>
            <upper>1e+16</upper>
          </limit>
          <dynamics>
            <spring_reference>0</spring_reference>
            <spring_stiffness>0</spring_stiffness>
          </dynamics>
        </axis>
      </joint>
      <joint name='create::right_wheel' type='revolute'>
        <parent>create::base</parent>
        <child>create::right_wheel</child>
        <axis>
          <xyz>0 1 0</xyz>
          <use_parent_model_frame>1</use_parent_model_frame>
          <limit>
            <lower>-1e+16</lower>
            <upper>1e+16</upper>
          </limit>
          <dynamics>
            <spring_reference>0</spring_reference>
            <spring_stiffness>0</spring_stiffness>
          </dynamics>
        </axis>
      </joint>
      <link name='kinect::link'>
        <inertial>
          <mass>0.1</mass>
          <inertia>
            <ixx>1</ixx>
            <ixy>0</ixy>
            <ixz>0</ixz>
            <iyy>1</iyy>
            <iyz>0</iyz>
            <izz>1</izz>
          </inertia>
        </inertial>
        <collision name='collision'>
          <geometry>
            <box>
              <size>0.073 0.276 0.072</size>
            </box>
          </geometry>
          <max_contacts>10</max_contacts>
          <surface>
            <contact>
              <ode/>
            </contact>
            <bounce/>
            <friction>
              <torsional>
                <ode/>
              </torsional>
              <ode/>
            </friction>
          </surface>
        </collision>
        <visual name='visual'>
          <geometry>
            <mesh>
              <uri>model://kinect/meshes/kinect.dae</uri>
            </mesh>
          </geometry>
        </visual>
        <sensor name='camera' type='depth'>
          <update_rate>20</update_rate>
          <camera name='__default__'>
            <horizontal_fov>1.0472</horizontal_fov>
            <image>
              <width>640</width>
              <height>480</height>
              <format>R8G8B8</format>
            </image>
            <clip>
              <near>0.05</near>
              <far>3</far>
            </clip>
          </camera>
        </sensor>
        <pose frame=''>-0.087098 0 0.303857 0 -0 0</pose>
        <self_collide>0</self_collide>
        <kinematic>0</kinematic>
      </link>
      <joint name='create_rack' type='revolute'>
        <parent>create::base</parent>
        <child>rack</child>
        <axis>
          <xyz>0 0 1</xyz>
          <limit>
            <lower>0</lower>
            <upper>0</upper>
          </limit>
          <use_parent_model_frame>1</use_parent_model_frame>
          <dynamics>
            <spring_reference>0</spring_reference>
            <spring_stiffness>0</spring_stiffness>
          </dynamics>
        </axis>
      </joint>
      <joint name='kinect_rack' type='revolute'>
        <parent>kinect::link</parent>
        <child>rack</child>
        <axis>
          <xyz>0 0 1</xyz>
          <limit>
            <lower>0</lower>
            <upper>0</upper>
          </limit>
          <use_parent_model_frame>1</use_parent_model_frame>
          <dynamics>
            <spring_reference>0</spring_reference>
            <spring_stiffness>0</spring_stiffness>
          </dynamics>
        </axis>
      </joint>
      <joint name='joint_laser' type='revolute'>
        <parent>rack</parent>
        <child>laser</child>
        <axis>
          <xyz>0 0 0</xyz>
          <limit>
            <lower>0</lower>
            <upper>0</upper>
          </limit>
          <use_parent_model_frame>0</use_parent_model_frame>
          <dynamics>
            <spring_reference>0</spring_reference>
            <spring_stiffness>0</spring_stiffness>
          </dynamics>
        </axis>
      </joint>
      <joint name='pan_joint_left' type='revolute'>
        <pose frame=''>0 0 0 0 -0 0</pose>
        <child>camera_bottom_body_left</child>
        <parent>camera_column_body_left</parent>
        <axis>
          <xyz>0 1 0</xyz>
          <limit>
            <lower>0</lower>
            <upper>0</upper>
          </limit>
          <use_parent_model_frame>0</use_parent_model_frame>
          <dynamics>
            <spring_reference>0</spring_reference>
            <spring_stiffness>0</spring_stiffness>
          </dynamics>
        </axis>
      </joint>
      <joint name='tilt_joint_left' type='revolute'>
        <pose frame=''>0 0 0 0 -0 0</pose>
        <child>camera_column_body_left</child>
        <parent>camera_top_body_left</parent>
        <axis>
          <xyz>1 0 0</xyz>
          <limit>
            <lower>0</lower>
            <upper>0</upper>
          </limit>
          <use_parent_model_frame>0</use_parent_model_frame>
          <dynamics>
            <spring_reference>0</spring_reference>
            <spring_stiffness>0</spring_stiffness>
          </dynamics>
        </axis>
      </joint>
      <joint name='camera_left' type='revolute'>
        <pose frame=''>0 0 0 0 -0 0</pose>
        <child>camera_bottom_body_left</child>
        <parent>rack</parent>
        <axis>
          <xyz>0 0 0</xyz>
          <limit>
            <lower>0</lower>
            <upper>0</upper>
          </limit>
          <use_parent_model_frame>0</use_parent_model_frame>
          <dynamics>
            <spring_reference>0</spring_reference>
            <spring_stiffness>0</spring_stiffness>
          </dynamics>
        </axis>
      </joint>
      <joint name='pan_joint_right' type='revolute'>
        <pose frame=''>0 0 0 0 -0 0</pose>
        <child>camera_bottom_body_right</child>
        <parent>camera_column_body_right</parent>
        <axis>
          <xyz>0 1 0</xyz>
          <limit>
            <lower>0</lower>
            <upper>0</upper>
          </limit>
          <use_parent_model_frame>0</use_parent_model_frame>
          <dynamics>
            <spring_reference>0</spring_reference>
            <spring_stiffness>0</spring_stiffness>
          </dynamics>
        </axis>
      </joint>
      <joint name='tilt_joint_right' type='revolute'>
        <pose frame=''>0 0 0 0 -0 0</pose>
        <child>camera_column_body_right</child>
        <parent>camera_top_body_right</parent>
        <axis>
          <xyz>1 0 0</xyz>
          <limit>
            <lower>0</lower>
            <upper>0</upper>
          </limit>
          <use_parent_model_frame>0</use_parent_model_frame>
          <dynamics>
            <spring_reference>0</spring_reference>
            <spring_stiffness>0</spring_stiffness>
          </dynamics>
        </axis>
      </joint>
      <joint name='camera_right' type='revolute'>
        <pose frame=''>0 0 0 0 -0 0</pose>
        <child>camera_bottom_body_right</child>
        <parent>rack</parent>
        <axis>
          <xyz>0 0 0</xyz>
          <limit>
            <lower>0</lower>
            <upper>0</upper>
          </limit>
          <use_parent_model_frame>0</use_parent_model_frame>
          <dynamics>
            <spring_reference>0</spring_reference>
            <spring_stiffness>0</spring_stiffness>
          </dynamics>
        </axis>
      </joint>
      <pose frame=''>-3 -8 0 0 -0 0</pose>
    </model>
    <state world_name='default'>
      <sim_time>63 381000000</sim_time>
      <real_time>64 92362942</real_time>
      <wall_time>1500487331 999960157</wall_time>
      <iterations>63381</iterations>
      <model name='ground_plane'>
        <pose frame=''>0 0 0 0 -0 0</pose>
        <scale>1 1 1</scale>
        <link name='link'>
          <pose frame=''>0 0 0 0 -0 0</pose>
          <velocity>0 0 0 0 -0 0</velocity>
          <acceleration>0 0 0 0 -0 0</acceleration>
          <wrench>0 0 0 0 -0 0</wrench>
        </link>
      </model>
      <model name='octa'>
        <pose frame=''>0 0 0 0 -0 0</pose>
        <scale>1 1 1</scale>
        <link name='Wall_11'>
          <pose frame=''>0 -10 0 0 -0 0</pose>
          <velocity>0 0 0 0 -0 0</velocity>
          <acceleration>0 0 0 0 -0 0</acceleration>
          <wrench>0 0 0 0 -0 0</wrench>
        </link>
        <link name='Wall_12'>
          <pose frame=''>8 -8 0 0 -0 0.785398</pose>
          <velocity>0 0 0 0 -0 0</velocity>
          <acceleration>0 0 0 0 -0 0</acceleration>
          <wrench>0 0 0 0 -0 0</wrench>
        </link>
        <link name='Wall_13'>
          <pose frame=''>10 0 0 0 -0 1.5708</pose>
          <velocity>0 0 0 0 -0 0</velocity>
          <acceleration>0 0 0 0 -0 0</acceleration>
          <wrench>0 0 0 0 -0 0</wrench>
        </link>
        <link name='Wall_14'>
          <pose frame=''>8 8 0 0 -0 2.35619</pose>
          <velocity>0 0 0 0 -0 0</velocity>
          <acceleration>0 0 0 0 -0 0</acceleration>
          <wrench>0 0 0 0 -0 0</wrench>
        </link>
        <link name='Wall_15'>
          <pose frame=''>0 10 0 0 -0 3.14159</pose>
          <velocity>0 0 0 0 -0 0</velocity>
          <acceleration>0 0 0 0 -0 0</acceleration>
          <wrench>0 0 0 0 -0 0</wrench>
        </link>
        <link name='Wall_16'>
          <pose frame=''>-8 8 0 0 0 -2.35619</pose>
          <velocity>0 0 0 0 -0 0</velocity>
          <acceleration>0 0 0 0 -0 0</acceleration>
          <wrench>0 0 0 0 -0 0</wrench>
        </link>
        <link name='Wall_17'>
          <pose frame=''>-10 0 0 0 0 -1.5708</pose>
          <velocity>0 0 0 0 -0 0</velocity>
          <acceleration>0 0 0 0 -0 0</acceleration>
          <wrench>0 0 0 0 -0 0</wrench>
        </link>
        <link name='Wall_18'>
          <pose frame=''>-8 -8 0 0 0 -0.785398</pose>
          <velocity>0 0 0 0 -0 0</velocity>
          <acceleration>0 0 0 0 -0 0</acceleration>
          <wrench>0 0 0 0 -0 0</wrench>
        </link>
        <link name='Wall_2'>
          <pose frame=''>0 -6 0 0 -0 0</pose>
          <velocity>0 0 0 0 -0 0</velocity>
          <acceleration>0 0 0 0 -0 0</acceleration>
          <wrench>0 0 0 0 -0 0</wrench>
        </link>
        <link name='Wall_3'>
          <pose frame=''>5 -5 0 0 -0 0.785398</pose>
          <velocity>0 0 0 0 -0 0</velocity>
          <acceleration>0 0 0 0 -0 0</acceleration>
          <wrench>0 0 0 0 -0 0</wrench>
        </link>
        <link name='Wall_4'>
          <pose frame=''>6 0 0 0 -0 1.5708</pose>
          <velocity>0 0 0 0 -0 0</velocity>
          <acceleration>0 0 0 0 -0 0</acceleration>
          <wrench>0 0 0 0 -0 0</wrench>
        </link>
        <link name='Wall_5'>
          <pose frame=''>5 5 0 0 -0 2.35619</pose>
          <velocity>0 0 0 0 -0 0</velocity>
          <acceleration>0 0 0 0 -0 0</acceleration>
          <wrench>0 0 0 0 -0 0</wrench>
        </link>
        <link name='Wall_6'>
          <pose frame=''>0 6 0 0 -0 3.14159</pose>
          <velocity>0 0 0 0 -0 0</velocity>
          <acceleration>0 0 0 0 -0 0</acceleration>
          <wrench>0 0 0 0 -0 0</wrench>
        </link>
        <link name='Wall_7'>
          <pose frame=''>-5 5 0 0 0 -2.35619</pose>
          <velocity>0 0 0 0 -0 0</velocity>
          <acceleration>0 0 0 0 -0 0</acceleration>
          <wrench>0 0 0 0 -0 0</wrench>
        </link>
        <link name='Wall_8'>
          <pose frame=''>-6 0 0 0 0 -1.5708</pose>
          <velocity>0 0 0 0 -0 0</velocity>
          <acceleration>0 0 0 0 -0 0</acceleration>
          <wrench>0 0 0 0 -0 0</wrench>
        </link>
        <link name='Wall_9'>
          <pose frame=''>-5 -5 0 0 0 -0.785398</pose>
          <velocity>0 0 0 0 -0 0</velocity>
          <acceleration>0 0 0 0 -0 0</acceleration>
          <wrench>0 0 0 0 -0 0</wrench>
        </link>
      </model>
      <model name='turtlebot'>
        <pose frame=''>-3.00162 -7.99707 0.000693 -0.000329 -0.020618 0.001136</pose>
        <scale>1 1 1</scale>
        <link name='camera_bottom_body_left'>
          <pose frame=''>-3.03649 -7.92103 0.232397 -1.57033 -0.020616 0.001136</pose>
          <velocity>0.000109 -8e-05 -2.2e-05 0.001096 0.000799 5e-05</velocity>
          <acceleration>-0.004463 -0.492148 -2.26229 1.9358 0.787372 0.068118</acceleration>
          <wrench>-0.002231 -0.246074 -1.13115 0 -0 0</wrench>
        </link>
        <link name='camera_bottom_body_right'>
          <pose frame=''>-3.03632 -8.07303 0.232448 -1.57033 -0.020616 0.001136</pose>
          <velocity>4.2e-05 0.000823 0.000199 -0.001264 0.000365 3e-06</velocity>
          <acceleration>-0.295545 1.23038 -1.78378 -1.90676 -0.906664 -0.00631</acceleration>
          <wrench>-0.147772 0.615192 -0.891888 0 -0 0</wrench>
        </link>
        <link name='camera_column_body_left'>
          <pose frame=''>-3.0268 -7.92101 0.2476 -1.57033 -0.020616 0.001136</pose>
          <velocity>0.000121 -9.8e-05 -2.6e-05 0.001097 0.0008 5.2e-05</velocity>
          <acceleration>0.009064 -0.524145 -2.26515 1.93839 0.790726 0.069069</acceleration>
          <wrench>0.004532 -0.262073 -1.13258 0 -0 0</wrench>
        </link>
        <link name='camera_column_body_right'>
          <pose frame=''>-3.02663 -8.07301 0.247651 -1.57033 -0.020616 0.001136</pose>
          <velocity>4.7e-05 0.000842 0.000199 -0.001258 0.000365 2e-06</velocity>
          <acceleration>-0.310783 1.25858 -1.77162 -1.89577 -0.905231 -0.008886</acceleration>
          <wrench>-0.155392 0.629291 -0.88581 0 -0 0</wrench>
        </link>
        <link name='camera_top_body_left'>
          <pose frame=''>-3.05669 -7.92105 0.241983 -1.5697 0.020616 3.14114</pose>
          <velocity>0.000114 -8.4e-05 -2.5e-05 0.00109 0.000796 5.2e-05</velocity>
          <acceleration>-0.003311 -0.497593 -2.26968 1.92546 0.774942 0.06874</acceleration>
          <wrench>-0.001656 -0.248797 -1.13484 0 -0 0</wrench>
        </link>
        <link name='camera_top_body_right'>
          <pose frame=''>-3.05652 -8.07305 0.242034 -1.56971 0.020617 3.14114</pose>
          <velocity>4.9e-05 0.000831 0.000192 -0.001297 0.000364 1e-06</velocity>
          <acceleration>-0.294536 1.24147 -1.81743 -1.97406 -0.914569 -0.010268</acceleration>
          <wrench>-0.147268 0.620736 -0.908716 0 -0 0</wrench>
        </link>
        <link name='create::base'>
          <pose frame=''>-3.00162 -7.99707 0.000695 -0.00033 -0.020619 0.001136</pose>
          <velocity>4e-06 1.4e-05 -0.000313 -0.004662 0.001403 -0.000477</velocity>
          <acceleration>0.098499 -0.129744 -2.54418 2.97712 0.257753 -0.373001</acceleration>
          <wrench>0.220047 -0.289849 -5.68369 0 -0 0</wrench>
        </link>
        <link name='create::left_wheel'>
          <pose frame=''>-3.00243 -7.86706 0.03296 -0.000366 -0.014573 0.001134</pose>
          <velocity>0.000108 0.000343 -0.079356 0.004399 0.00142 -0.000476</velocity>
          <acceleration>0.068532 0.347774 -120.315 -2.22237 0.293895 -0.18725</acceleration>
          <wrench>0.000685 0.003478 -1.20315 0 -0 0</wrench>
        </link>
        <link name='create::right_wheel'>
          <pose frame=''>-3.00213 -8.12706 0.033028 -0.000372 -0.014906 0.001134</pose>
          <velocity>5e-05 0.000211 0.034862 -0.006517 0.001396 -0.000429</velocity>
          <acceleration>0.122913 0.175024 93.8081 1.68463 0.276903 -0.118292</acceleration>
          <wrench>0.001229 0.00175 0.938081 0 -0 0</wrench>
        </link>
        <link name='kinect::link'>
          <pose frame=''>-3.09497 -7.99707 0.302689 -0.00033 -0.020618 0.001136</pose>
          <velocity>0.000113 0.001063 -0.000154 -0.003697 0.00044 -0.000187</velocity>
          <acceleration>-0.280718 1.71148 -2.53334 -1.24185 -1.18259 -0.174137</acceleration>
          <wrench>-0.028072 0.171148 -0.253334 0 -0 0</wrench>
        </link>
        <link name='laser'>
          <pose frame=''>-2.84896 -7.99686 0.115863 -0.000328 -0.020616 0.001136</pose>
          <velocity>9.5e-05 -8.5e-05 -0.000263 0.000662 0.000629 4.1e-05</velocity>
          <acceleration>0.202352 -0.542591 -2.51074 1.08918 0.680415 0.050609</acceleration>
          <wrench>0.020235 -0.054259 -0.251074 0 -0 0</wrench>
        </link>
        <link name='rack'>
          <pose frame=''>-3.00162 -7.99707 0.000693 -0.000329 -0.020618 0.001136</pose>
          <velocity>-1.1e-05 -8.4e-05 -0.000222 -0.003005 0.001094 -3.1e-05</velocity>
          <acceleration>0.109904 -0.412223 -2.4456 -0.06245 0.334767 -0.220117</acceleration>
          <wrench>0.245525 -0.920906 -5.46347 0 -0 0</wrench>
        </link>
      </model>
      <light name='sun'>
        <pose frame=''>0 0 10 0 -0 0</pose>
      </light>
    </state>
    <gui fullscreen='0'>
      <camera name='user_camera'>
        <pose frame=''>23.5042 -7.99461 40.4664 0 0.985797 2.65619</pose>
        <view_controller>orbit</view_controller>
        <projection_type>perspective</projection_type>
      </camera>
    </gui>
  </world>
</sdf>
